<?xml version="1.0" encoding="utf-8"?>
<!--First version of this URDF was automatically created by SolidWorks to URDF Exporter!
    as part of eYSIP 2022 
    Originally created by Stephen Brawner (brawner@gmail.com) 
    Commit Version: 1.6.0-4-g7f85cfe  Build Version: 1.6.7995.38578
    For more information, please see http://wiki.ros.org/sw_urdf_exporter 

    This version of the URDF is made after a lot of simplification by the e-Yantra Team (Arjun Sadananda) -->
<robot
  name="hola_bot">

  <!-- Chassis -->

  <link
    name="base_link">
    <inertial>
      <origin
        xyz="0 0 0"
        rpy="0 0 0" />
      <mass
        value="1" />
      <inertia
        ixx="0.005627"
        ixy="0"
        ixz="0"
        iyy="0.005627"
        iyz="0"
        izz="0.01125" />
    </inertial>
    <visual>
      <origin
        xyz="0 0 0"
        rpy="0 0 1.57" />
      <geometry>
        <mesh
          filename="package://your_package_name/meshes/base_link.obj" />
      </geometry>
    </visual>
    <collision>
      <origin
        xyz="0 0 -0.01"
        rpy="0 0 1.57" />
      <geometry>
        <cylinder radius="0.15" length="0.005"/>
      </geometry>
    </collision>
  </link>


  <!-- Front Wheel -->

  <!-- Front Wheel Link -->
  <link
    name="front_wheel">
    <inertial>
      <origin
        xyz="0 0 0"
        rpy="0 0 0" />
      <mass
        value="0.060" />
      <inertia
        ixx="0.00001352"
        ixy="0"
        ixz="0"
        iyy="0.000027"
        iyz="0"
        izz="0.00001352" />
    </inertial>
    <visual>
      <origin
        xyz="0 0 0"
        rpy="0 0 0" />
      <geometry>
        <mesh
          filename="package://your_package_name/meshes/wheel.STL" />
      </geometry>
    </visual>
    <collision>
      <origin
        xyz="0 -.01 0"
        rpy="1.57 0 0" />
      <geometry>
        <cylinder radius=".03" length="0.02"/>
      </geometry>
    </collision>
  </link>

  <!-- Front Wheel Joint -->

  <joint
    name="front_joint"
    type="revolute">
    <origin
      xyz="0 0.17483 0"
      rpy="0 0 0" />
    <parent
      link="base_link" />
    <child
      link="front_wheel" />
    <axis
      xyz="0 -1 0" />
    <limit
      effort="5"
      velocity="5" />
  </joint>
  
  <!-- Left Wheel -->

  <!-- Left Wheel Link -->
  <link
    name="left_wheel">
    <inertial>
      <origin
        xyz="0 0 0"
        rpy="0 0 0" />
      <mass
        value="0.060" />
      <inertia
        ixx="0.00001352"
        ixy="0"
        ixz="0"
        iyy="0.000027"
        iyz="0"
        izz="0.00001352" />
    </inertial>
    <visual>
      <origin
        xyz="0 0 0"
        rpy="0 0 0" />
      <geometry>
        <mesh
          filename="package://your_package_name/meshes/wheel.STL" />
      </geometry>
      <material
        name="">
        <color
          rgba="0.4 0.4 0.4 1" />
      </material>
    </visual>
    <collision>
      <origin
        xyz="0 -0.01 0"
        rpy="1.57 0 0" />
      <geometry>
        <cylinder radius=".03" length="0.02"/>
      </geometry>
    </collision>
  </link>

  <!-- Left Wheel Joint -->
  <joint
    name="left_joint"
    type="revolute">
    <origin
      xyz="-0.15154 -0.087275 0"
      rpy="0 0 2.094" />
    <parent
      link="base_link" />
    <child
      link="left_wheel" />
    <axis
      xyz="0 1 0" />
    <limit
      effort="5"
      velocity="5" />
  </joint>


  <!-- Right Wheel -->
  <!-- Right Wheel Link -->
  <link
    name="right_wheel">
    <inertial>
      <origin
        xyz="0 0 0"
        rpy="0 0 0" />
      <mass
        value="0.060" />
      <inertia
        ixx="0.00001352"
        ixy="0"
        ixz="0"
        iyy="0.000027"
        iyz="0"
        izz="0.00001352" />
    </inertial>
    <visual>
      <origin
        xyz="0 0 0"
        rpy="0 0 0" />
      <geometry>
        <mesh
          filename="package://your_package_name/meshes/wheel.STL" />
      </geometry>
      <material
        name="">
        <color
          rgba="0.4 0.4 0.4 1" />
      </material>
    </visual>
    <collision>
      <origin
        xyz="0 -0.01 0"
        rpy="1.57 0 0" />
      <geometry>
        <cylinder radius=".03" length="0.02"/>
      </geometry>
    </collision>
  </link>

  <!-- Right Wheel Joint -->

  <joint
    name="right_joint"
    type="revolute">
    <origin
      xyz="0.15154 -0.087275 0"
      rpy="0 0 -2.094" />
    <parent
      link="base_link" />
    <child
      link="right_wheel" />
    <axis
      xyz="0 1 0" />
    <limit
      effort="5"
      velocity="5" />
  </joint>


 <gazebo>
    <plugin name="object_controller" filename="libgazebo_ros_planar_move.so">
    </plugin>
  </gazebo>   

 <gazebo>
    <plugin name="right_force" filename="libcustom_force.so" >
      <bodyName>right_wheel</bodyName>
      <topicName>right_wheel_force</topicName>
    </plugin>
  </gazebo>

  <gazebo>
    <plugin name="left_force" filename="libcustom_force.so" >
      <bodyName>left_wheel</bodyName>
      <topicName>left_wheel_force</topicName>
    </plugin>
  </gazebo>

  <gazebo>
    <plugin name="front_force" filename="libcustom_force.so" >
      <bodyName>front_wheel</bodyName>
      <topicName>front_wheel_force</topicName>
    </plugin>
  </gazebo>
  
</robot>

   
